# try ... catch ... finally语句

`try...catch...finally` 语句是 JavaScript 中用于处理错误的一种机制。它允许你编写一段代码块，尝试执行可能会引发错误的操作，并在出现错误时捕获和处理该错误。

`try` 块是包含可能引发错误的代码的区域。如果在 `try` 块中的代码引发了错误，控制流会立即跳转到 `catch` 块。

`catch` 块是用于捕获和处理错误的区域。它包含一个或多个语句，用于定义在发生错误时要执行的操作。你可以在 `catch` 块中使用 `Error` 对象来访问有关错误的信息。

`finally` 块是一个可选的区域，用于定义在 `try` 块中的代码执行完毕后，无论是否出现错误，都要执行的操作。即使在 `catch` 块中使用了 `return` 语句，`finally` 块中的代码也会执行。

下面是 `try...catch...finally` 语句的基本语法：

```javascript
try {
  // 可能引发错误的代码
} catch (error) {
  // 处理错误的代码
} finally {
  // 最终要执行的代码
}
```

下面是一个示例，演示了如何使用 `try...catch...finally` 语句来处理错误：

```javascript
try {
  // 可能引发错误的代码
  throw new Error('这是一个自定义错误');
} catch (error) {
  // 处理错误的代码
  console.log('捕获到错误：', error.message);
} finally {
  // 最终要执行的代码
  console.log('无论是否有错误，这段代码都会执行');
}
```

在上面的示例中，我们在 `try` 块中使用 `throw` 语句抛出了一个自定义错误。然后，在 `catch` 块中，我们捕获到该错误并打印出错误消息。最后，在 `finally` 块中，我们打印出一条无论是否有错误都会执行的消息。
